Workbook

Sheet R0 - Calc
B1: ="SOC = "&10*(COLUMN()-2)&" [%]" -> SOC = 0 [%] | C1: ="SOC = "&10*(COLUMN()-2)&" [%]" -> SOC = 10 [%] | D1: ="SOC = "&10*(COLUMN()-2)&" [%]" -> SOC = 20 [%] | E1: ="SOC = "&10*(COLUMN()-2)&" [%]" -> SOC = 30 [%] | F1: ="SOC = "&10*(COLUMN()-2)&" [%]" -> SOC = 40 [%] | G1: ="SOC = "&10*(COLUMN()-2)&" [%]" -> SOC = 50 [%] | H1: ="SOC = "&10*(COLUMN()-2)&" [%]" -> SOC = 60 [%] | I1: ="SOC = "&10*(COLUMN()-2)&" [%]" -> SOC = 70 [%] | ... L1: ="SOC = "&10*(COLUMN()-2)&" [%]" -> SOC = 100 [%]
A2: ="I= "&1*(row()-1)&" [A]" -> I= 1 [A] | B2: 127 | C2: 50 | D2: 35 | E2: 25 | F2: 17 | G2: 15 | H2: 14 | I2: 13 | J2: 12.5 | K2: 11 | L2: 9 | M2: 0 | P2: row | Q2: {=min(BIN2DEC(W3)+SUM(MID(W4, ROW(INDIRECT("1:" & LEN(W4))), 1) * 2^(-ROW(INDIRECT("1:" & LEN(W4))))),15)} -> 1.6367188 | S2: rowcol_mul | T2: =Q6*Q7 -> 0.36064148 | Z2: Int_bin | AA2: frac_bin | AB2: Int_dec | AC2: Frac_dec
A3: ="I= "&1*(row()-1)&" [A]" -> I= 2 [A] | B3: 125 | C3: 40 | D3: 27 | E3: 20 | F3: 16 | G3: 14 | H3: 12 | I3: 11 | J3: 10 | K3: 9 | L3: 8 | M3: =M2+1 -> 1 | P3: col | Q3: {=min(10,BIN2DEC(W6)+SUM(MID(W7, ROW(INDIRECT("1:" & LEN(W7))), 1) * 2^(-ROW(INDIRECT("1:" & LEN(W7))))))} -> 1.5664062 | S3: rowcol_add | T3: =Q6+Q7 -> 1.203125 | V3: rowbin_int | W3: =Z3 -> 0001 | X3: Row : | Y3: =Y7-1 -> 1.64 | Z3: =dec2bin(rounddown(Y3,0),4) -> 0001 | AA3: =IF(Y3-rounddown(Y3,0)>=0.5, "1", "0") & IF(MOD(Y3-rounddown(Y3,0),0.5)>=0.25, "1", "0") & IF(MOD(MOD(Y3-rounddown(Y3,0),0.5),0.25)>=0.125, "1", "0") & IF(MOD(MOD(MOD(Y3-rounddown(Y3,0),0.5),0.25),0.125)>=0.0625, "1", "0") & IF(MOD(MOD(MOD(MOD(Y3-rounddown(Y3,0),0.5),0.25),0.125),0.0625)>=0.03125, "1", "0") & IF(MOD(MOD(MOD(MOD(MOD(Y3-rounddown(Y3,0),0.5),0.25),0.125),0.0625),0.03125)>=0.015625, "1", "0") & IF(MOD(MOD(MOD(MOD(MOD(MOD(Y3-rounddown(Y3,0),0.5),0.25),0.125),0.0625),0.03125),0.015625)>=0.0078125, "1", "0") & IF(MOD(MOD(MOD(MOD(MOD(MOD(MOD(Y3-rounddown(Y3,0),0.5),0.25),0.125),0.0625),0.03125),0.015625),0.0078125)>=0.00390625, "1", "0") -> 10100011 | AB3: 8.6 | AC3: {=SUM(MID(AA3, ROW(INDIRECT("1:" & LEN(AA3))), 1) * 2^(-ROW(INDIRECT("1:" & LEN(AA3)))))} -> 0.63671875 | AE3: row | AH3: 1.255
A4: ="I= "&1*(row()-1)&" [A]" -> I= 3 [A] | B4: 123 | C4: 32 | D4: 24 | E4: 19 | F4: 15 | G4: 13 | H4: 11 | I4: 10 | J4: 9.5 | K4: 8.5 | L4: 7.5 | M4: =M3+1 -> 2 | P4: rowint | Q4: =ROUNDDOWN(Q2,0) -> 1 | V4: rowbin_frac | W4: =AA3 -> 10100011 | X4: Col : | Y4: =Y6*0.100006103515625 -> 1.5670956 | Z4: =dec2bin(rounddown(Y4,0),4) -> 0001 | AA4: =IF(Y4-rounddown(Y4,0)>=0.5, "1", "0") & IF(MOD(Y4-rounddown(Y4,0),0.5)>=0.25, "1", "0") & IF(MOD(MOD(Y4-rounddown(Y4,0),0.5),0.25)>=0.125, "1", "0") & IF(MOD(MOD(MOD(Y4-rounddown(Y4,0),0.5),0.25),0.125)>=0.0625, "1", "0") & IF(MOD(MOD(MOD(MOD(Y4-rounddown(Y4,0),0.5),0.25),0.125),0.0625)>=0.03125, "1", "0") & IF(MOD(MOD(MOD(MOD(MOD(Y4-rounddown(Y4,0),0.5),0.25),0.125),0.0625),0.03125)>=0.015625, "1", "0") & IF(MOD(MOD(MOD(MOD(MOD(MOD(Y4-rounddown(Y4,0),0.5),0.25),0.125),0.0625),0.03125),0.015625)>=0.0078125, "1", "0") & IF(MOD(MOD(MOD(MOD(MOD(MOD(MOD(Y4-rounddown(Y4,0),0.5),0.25),0.125),0.0625),0.03125),0.015625),0.0078125)>=0.00390625, "1", "0") -> 10010001 | AB4: 4.0507812 | AC4: {=SUM(MID(AA4, ROW(INDIRECT("1:" & LEN(AA4))), 1) * 2^(-ROW(INDIRECT("1:" & LEN(AA4)))))} -> 0.56640625 | AE4: col
A5: ="I= "&1*(row()-1)&" [A]" -> I= 4 [A] | B5: 120 | C5: 25 | D5: 22 | E5: 18 | F5: 14 | G5: 12 | H5: 10.5 | I5: 9.5 | J5: 8.5 | K5: 7 | L5: 6 | M5: =M4+1 -> 3 | P5: colint | Q5: =ROUNDDOWN(Q3,0) -> 1 | AE5: =AH3-ROUNDDOWN(AH3,0) -> 0.255 | AH5: =IF(AE5>=0.5, "1", "0") & IF(MOD(AE5,0.5)>=0.25, "1", "0") & IF(MOD(MOD(AE5,0.5),0.25)>=0.125, "1", "0") & IF(MOD(MOD(MOD(AE5,0.5),0.25),0.125)>=0.0625, "1", "0") & IF(MOD(MOD(MOD(MOD(AE5,0.5),0.25),0.125),0.0625)>=0.03125, "1", "0") & IF(MOD(MOD(MOD(MOD(MOD(AE5,0.5),0.25),0.125),0.0625),0.03125)>=0.015625, "1", "0") & IF(MOD(MOD(MOD(MOD(MOD(MOD(AE5,0.5),0.25),0.125),0.0625),0.03125),0.015625)>=0.0078125, "1", "0") & IF(MOD(MOD(MOD(MOD(MOD(MOD(MOD(AE5,0.5),0.25),0.125),0.0625),0.03125),0.015625),0.0078125)>=0.00390625, "1", "0") -> 01000001
A6: ="I= "&1*(row()-1)&" [A]" -> I= 5 [A] | B6: 110 | C6: 20 | D6: 18 | E6: 17 | F6: 13 | G6: 11 | H6: 10 | I6: 9 | J6: 7.75 | K6: 6.75 | L6: 5.5 | M6: =M5+1 -> 4 | P6: rowfrac | Q6: =Q2 - ROUNDDOWN(Q2,0) -> 0.63671875 | V6: col_int | W6: =Z4 -> 0001 | X6: SOC | Y6: 15.67
A7: ="I= "&1*(row()-1)&" [A]" -> I= 6 [A] | B7: 95 | C7: 17 | D7: 15 | E7: 14 | F7: 12 | G7: 10 | H7: 9 | I7: 8 | J7: 7.25 | K7: 6.5 | L7: 5.25 | M7: =M6+1 -> 5 | P7: colfrac | Q7: =Q3 - ROUNDDOWN(Q3,0) -> 0.56640625 | V7: col_frac | W7: =AA4 -> 10010001 | X7: Current | Y7: 2.64
A8: ="I= "&1*(row()-1)&" [A]" -> I= 7 [A] | B8: 80 | C8: 16 | D8: 14 | E8: 13 | F8: 11 | G8: 9 | H8: 8 | I8: 7.5 | J8: 7 | K8: 6.25 | L8: 5.125 | M8: =M7+1 -> 6
A9: ="I= "&1*(row()-1)&" [A]" -> I= 8 [A] | B9: 71 | C9: 15 | D9: 13 | E9: 12 | F9: 10 | G9: 7.5 | H9: 6.75 | I9: 6.5 | J9: 6.25 | K9: 6 | L9: 5 | M9: =M8+1 -> 7 | P9: w11 | Q9: =1-(T3-T2) -> 0.15751648 | S9: =IF(Q9-rounddown(Q9,0)>=0.5, "1", "0") & IF(MOD(Q9-rounddown(Q9,0),0.5)>=0.25, "1", "0") & IF(MOD(MOD(Q9-rounddown(Q9,0),0.5),0.25)>=0.125, "1", "0") & IF(MOD(MOD(MOD(Q9-rounddown(Q9,0),0.5),0.25),0.125)>=0.0625, "1", "0") & IF(MOD(MOD(MOD(MOD(Q9-rounddown(Q9,0),0.5),0.25),0.125),0.0625)>=0.03125, "1", "0") & IF(MOD(MOD(MOD(MOD(MOD(Q9-rounddown(Q9,0),0.5),0.25),0.125),0.0625),0.03125)>=0.015625, "1", "0") & IF(MOD(MOD(MOD(MOD(MOD(MOD(Q9-rounddown(Q9,0),0.5),0.25),0.125),0.0625),0.03125),0.015625)>=0.0078125, "1", "0") & IF(MOD(MOD(MOD(MOD(MOD(MOD(MOD(Q9-rounddown(Q9,0),0.5),0.25),0.125),0.0625),0.03125),0.015625),0.0078125)>=0.00390625, "1", "0") -> 00101000 | T9: =CONCAT(bin2hex(left(S9,4)), bin2hex(RIGHT(S9,4))) -> 28 | X9: =2^(-14) -> 6.1035156e-05
A10: ="I= "&1*(row()-1)&" [A]" -> I= 9 [A] | B10: 63 | C10: 14 | D10: 12 | E10: 10 | F10: 9.25 | G10: 6 | H10: 5.75 | I10: 5.5 | J10: 5.375 | K10: 5.125 | L10: 4.9 | M10: =M9+1 -> 8 | P10: w12 | Q10: =Q7-T2 -> 0.20576477 | R10: =Q10*2^(16) -> 13485 | S10: =IF(Q10-rounddown(Q10,0)>=0.5, "1", "0") & IF(MOD(Q10-rounddown(Q10,0),0.5)>=0.25, "1", "0") & IF(MOD(MOD(Q10-rounddown(Q10,0),0.5),0.25)>=0.125, "1", "0") & IF(MOD(MOD(MOD(Q10-rounddown(Q10,0),0.5),0.25),0.125)>=0.0625, "1", "0") & IF(MOD(MOD(MOD(MOD(Q10-rounddown(Q10,0),0.5),0.25),0.125),0.0625)>=0.03125, "1", "0") & IF(MOD(MOD(MOD(MOD(MOD(Q10-rounddown(Q10,0),0.5),0.25),0.125),0.0625),0.03125)>=0.015625, "1", "0") & IF(MOD(MOD(MOD(MOD(MOD(MOD(Q10-rounddown(Q10,0),0.5),0.25),0.125),0.0625),0.03125),0.015625)>=0.0078125, "1", "0") & IF(MOD(MOD(MOD(MOD(MOD(MOD(MOD(Q10-rounddown(Q10,0),0.5),0.25),0.125),0.0625),0.03125),0.015625),0.0078125)>=0.00390625, "1", "0") -> 00110100 | T10: =CONCAT(bin2hex(left(S10,4)), bin2hex(RIGHT(S10,4))) -> 34
A11: ="I= "&1*(row()-1)&" [A]" -> I= 10 [A] | B11: 54 | C11: 13 | D11: 11 | E11: 9.5 | F11: 9 | G11: 5 | H11: 4.75 | I11: 4.5 | J11: 4.25 | K11: 4.125 | L11: 4 | M11: =M10+1 -> 9 | P11: w21 | Q11: =Q6-T2 -> 0.27607727 | S11: =IF(Q11-rounddown(Q11,0)>=0.5, "1", "0") & IF(MOD(Q11-rounddown(Q11,0),0.5)>=0.25, "1", "0") & IF(MOD(MOD(Q11-rounddown(Q11,0),0.5),0.25)>=0.125, "1", "0") & IF(MOD(MOD(MOD(Q11-rounddown(Q11,0),0.5),0.25),0.125)>=0.0625, "1", "0") & IF(MOD(MOD(MOD(MOD(Q11-rounddown(Q11,0),0.5),0.25),0.125),0.0625)>=0.03125, "1", "0") & IF(MOD(MOD(MOD(MOD(MOD(Q11-rounddown(Q11,0),0.5),0.25),0.125),0.0625),0.03125)>=0.015625, "1", "0") & IF(MOD(MOD(MOD(MOD(MOD(MOD(Q11-rounddown(Q11,0),0.5),0.25),0.125),0.0625),0.03125),0.015625)>=0.0078125, "1", "0") & IF(MOD(MOD(MOD(MOD(MOD(MOD(MOD(Q11-rounddown(Q11,0),0.5),0.25),0.125),0.0625),0.03125),0.015625),0.0078125)>=0.00390625, "1", "0") -> 01000110 | T11: =CONCAT(bin2hex(left(S11,4)), bin2hex(RIGHT(S11,4))) -> 46
A12: ="I= "&1*(row()-1)&" [A]" -> I= 11 [A] | B12: 47 | C12: 12.5 | D12: 10.5 | E12: 9 | F12: 8 | G12: 4.5 | H12: 4.375 | I12: 4.25 | J12: 4.15 | K12: 4 | L12: 3.875 | M12: =M11+1 -> 10 | P12: w22 | Q12: =T2 -> 0.36064148 | S12: =IF(Q12-rounddown(Q12,0)>=0.5, "1", "0") & IF(MOD(Q12-rounddown(Q12,0),0.5)>=0.25, "1", "0") & IF(MOD(MOD(Q12-rounddown(Q12,0),0.5),0.25)>=0.125, "1", "0") & IF(MOD(MOD(MOD(Q12-rounddown(Q12,0),0.5),0.25),0.125)>=0.0625, "1", "0") & IF(MOD(MOD(MOD(MOD(Q12-rounddown(Q12,0),0.5),0.25),0.125),0.0625)>=0.03125, "1", "0") & IF(MOD(MOD(MOD(MOD(MOD(Q12-rounddown(Q12,0),0.5),0.25),0.125),0.0625),0.03125)>=0.015625, "1", "0") & IF(MOD(MOD(MOD(MOD(MOD(MOD(Q12-rounddown(Q12,0),0.5),0.25),0.125),0.0625),0.03125),0.015625)>=0.0078125, "1", "0") & IF(MOD(MOD(MOD(MOD(MOD(MOD(MOD(Q12-rounddown(Q12,0),0.5),0.25),0.125),0.0625),0.03125),0.015625),0.0078125)>=0.00390625, "1", "0") -> 01011100 | T12: =CONCAT(bin2hex(left(S12,4)), bin2hex(RIGHT(S12,4))) -> 5C | U12: ="0101" -> 0101
A13: ="I= "&1*(row()-1)&" [A]" -> I= 12 [A] | B13: 41 | C13: 12 | D13: 10 | E13: 8 | F13: 7 | G13: 4 | H13: 3.875 | I13: 3.75 | J13: 3.625 | K13: 3.5 | L13: 3.4 | M13: =M12+1 -> 11 | T13: {=SUM(MID(U12, ROW(INDIRECT("1:" & LEN(U12))), 1) * 2^(-ROW(INDIRECT("1:" & LEN(U12)))))} -> 0.3125
A14: ="I= "&1*(row()-1)&" [A]" -> I= 13 [A] | B14: 36 | C14: 11 | D14: 9.5 | E14: 7.5 | F14: 6 | G14: 3.75 | H14: 3.5 | I14: 3.375 | J14: 3.125 | K14: 3 | L14: 2.9 | M14: =M13+1 -> 12 | P14: x11 | Q14: {=INDEX(B2:L17,ROUNDDOWN(Q2,0)+1,ROUNDDOWN(Q3,0)+1)} -> 40
A15: ="I= "&1*(row()-1)&" [A]" -> I= 14 [A] | B15: 33 | C15: 10 | D15: 9 | E15: 7 | F15: 5.5 | G15: 3.25 | H15: 3.125 | I15: 3 | J15: 2.9 | K15: 2.88 | L15: 2.8 | M15: =M14+1 -> 13 | P15: x12 | Q15: {=INDEX(B2:L17,ROUNDDOWN(Q2,0)+1,min(ROUNDDOWN(Q3,0)+2,11))} -> 27
A16: ="I= "&1*(row()-1)&" [A]" -> I= 15 [A] | B16: 30 | C16: 9 | D16: 8.5 | E16: 6.5 | F16: 5 | G16: 3 | H16: 2.8 | I16: 2.75 | J16: 2.7 | K16: 2.67 | L16: 2.6 | M16: =M15+1 -> 14 | P16: x21 | Q16: {=INDEX(B2:L17,min(ROUNDDOWN(Q2,0)+2,16),ROUNDDOWN(Q3,0)+1)} -> 32
A17: ="I= "&1*(row()-1)&" [A]" -> I= 16 [A] | B17: 28 | C17: 7 | D17: 6.8 | E17: 6.3 | F17: 4.9 | G17: 2.75 | H17: 2.6 | I17: 2.55 | J17: 2.5 | K17: 2.45 | L17: 2.4 | M17: =M16+1 -> 15 | P17: x22 | Q17: {=INDEX(B2:L17,min(ROUNDDOWN(Q2,0)+2,16),min(ROUNDDOWN(Q3,0)+2,11))} -> 24
B18: 0 | C18: =B18+1 -> 1 | D18: =C18+1 -> 2 | E18: =D18+1 -> 3 | F18: =E18+1 -> 4 | G18: =F18+1 -> 5 | H18: =G18+1 -> 6 | I18: =H18+1 -> 7 | J18: =I18+1 -> 8 | ... L18: =K18+1 -> 10
P19: r_val | Q19: =Q9*Q14+Q15*Q10+Q16*Q11+Q17*Q12 -> 29.346176 | T19: SOC = | U19: =Q3*10 -> 15.664062
H20: =G17*0.25+H17*0.75 -> 2.6375 | P20: r_val_bin | Q20: =DEC2BIN(Q19) -> 11101
V21: w11 | W21: =IF(T3>=1,T2-(T3-1),1-(T3-T2)) -> 0.15751648
P22: =DEC2HEX(Q19) -> 1D | V22: w12 | W22: =Q7-T2 -> 0.20576477
D23: indx 13 | E23: =D3 -> 27 | F23: =DEC2HEX(E23) -> 1B | G23: x11 | R23: w1_bin | S23: ="0111010000000000" -> 0111010000000000 | V23: w21 | W23: =Q6-T2 -> 0.27607727
D24: indx 14 | E24: =E3 -> 20 | F24: =DEC2HEX(E24) -> 14 | G24: x12 | R24: w1_bindec | S24: {=SUM(MID(S23, ROW(INDIRECT("1:" & LEN(S23))), 1) * 2^(-ROW(INDIRECT("1:" & LEN(S23)))))} -> 0.453125 | V24: w22 | W24: =T2 -> 0.36064148 | AH24: =2^(-6) -> 0.015625
D25: indx 24 | E25: =D4 -> 24 | F25: =DEC2HEX(E25) -> 18 | G25: x21 | R25: w2_bin | S25: ="1000110000000000" -> 1000110000000000 | Y25: =mod(0.2664,0.25) -> 0.0164
D26: indx 25 | E26: =E4 -> 19 | F26: =DEC2HEX(E26) -> 13 | G26: x22 | R26: w2_bin2dec | S26: {=SUM(MID(S25, ROW(INDIRECT("1:" & LEN(S25))), 1) * 2^(-ROW(INDIRECT("1:" & LEN(S25)))))} -> 0.546875
I27: =5*11+0 -> 55 | AA27: ="1100" -> 1100
AA28: =AA27+"0100" -> 1200 | AJ28: =2^(-14) -> 6.1035156e-05
F29: 110010
R30: r_valbin | S30: ="00001111110100000000000000000000" -> 00001111110100000000000000000000
G31: =DEC2HEX(E23) -> 1B | R31: r_valbin2dec | S31: {=SUM(MID(S30, ROW(INDIRECT("1:" & LEN(S30))), 1) * 2^(-ROW(INDIRECT("1:" & LEN(S30)))))} -> 0.061767578
R33: o_val | S33: =left(S30,16) -> 0000111111010000
R34: r_R0_int | S34: =left(S33,8) -> 00001111
R35: r_R0_frac | S35: =RIGHT(S33,8) -> 11010000
R36: r_R0_dec | S36: {=BIN2DEC(S34)+SUM(MID(S35, ROW(INDIRECT("1:" & LEN(S35))), 1) * 2^(-ROW(INDIRECT("1:" & LEN(S35)))))} -> 15.8125
B38: {=INDEX(A2:L17, INT(E38/ 11), MOD(E38, 11) + 1+1)} -> 15 | E38: 5 | G38: INPUT_ ELEMENTINDEX (11*row+col) | H38: 22 | J38: HEXValue
B39: 14 | G39: Tableval | H39: {=INDEX(A2:L17, INT(H38 / 11) + 1, MOD(H38, 11) + 2)} -> 123 | I39: x11_integer | J39: =DEC2HEX(H39) -> 7B
B40: 13 | G40: Column | H40: =SUBSTITUTE(ADDRESS(1, MOD(H38, 11) + 2, 4), "1", "") -> B | I40: x21 | R40: x1_bin | S40: ="0001001000000000" -> 0001001000000000 | V40: ="1192" -> 1192
B41: 12 | G41: Row | H41: =INT(H38/11)+2 -> 4 | R41: x1_intpart | S41: =left(S40,8) -> 00010010 | V41: =left(V40,3) -> 119
B42: 11 | R42: x1_bin2dec | S42: =BIN2DEC(S41) -> 18
...

Sheet R0
B1: SOC = 0 [%] | C1: SOC = 10 [%] | D1: SOC = 20 [%] | E1: SOC = 30 [%] | F1: SOC = 40 [%] | G1: SOC = 50 [%] | H1: SOC = 60 [%] | I1: SOC = 70 [%] | J1: SOC = 80 [%] | K1: SOC = 90 [%] | L1: SOC = 100 [%]
A2: I= 1 [A] | B2: 127 | C2: 50 | D2: 35 | E2: 25 | F2: 17 | G2: 15 | H2: 14 | I2: 13 | J2: 12.5 | K2: 11 | L2: 9
A3: I= 2 [A] | B3: 125 | C3: 40 | D3: 27 | E3: 20 | F3: 16 | G3: 14 | H3: 12 | I3: 11 | J3: 10 | K3: 9 | L3: 8
A4: I= 3 [A] | B4: 123 | C4: 32 | D4: 24 | E4: 19 | F4: 15 | G4: 13 | H4: 11 | I4: 10 | J4: 9.5 | K4: 8.5 | L4: 7.5
A5: I= 4 [A] | B5: 120 | C5: 25 | D5: 22 | E5: 18 | F5: 14 | G5: 12 | H5: 10.5 | I5: 9.5 | J5: 8.5 | K5: 7 | L5: 6
A6: I= 5 [A] | B6: 110 | C6: 20 | D6: 18 | E6: 17 | F6: 13 | G6: 11 | H6: 10 | I6: 9 | J6: 7.75 | K6: 6.75 | L6: 5.5
A7: I= 6 [A] | B7: 95 | C7: 17 | D7: 15 | E7: 14 | F7: 12 | G7: 10 | H7: 9 | I7: 8 | J7: 7.25 | K7: 6.5 | L7: 5.25
A8: I= 7 [A] | B8: 80 | C8: 16 | D8: 14 | E8: 13 | F8: 11 | G8: 9 | H8: 8 | I8: 7.5 | J8: 7 | K8: 6.25 | L8: 5.125
A9: I= 8 [A] | B9: 71 | C9: 15 | D9: 13 | E9: 12 | F9: 10 | G9: 7.5 | H9: 6.75 | I9: 6.5 | J9: 6.25 | K9: 6 | L9: 5
A10: I= 9 [A] | B10: 63 | C10: 14 | D10: 12 | E10: 10 | F10: 9.25 | G10: 6 | H10: 5.75 | I10: 5.5 | J10: 5.375 | K10: 5.125 | L10: 4.9
A11: I= 10 [A] | B11: 54 | C11: 13 | D11: 11 | E11: 9.5 | F11: 9 | G11: 5 | H11: 4.75 | I11: 4.5 | J11: 4.25 | K11: 4.125 | L11: 4
A12: I= 11 [A] | B12: 47 | C12: 12.5 | D12: 10.5 | E12: 9 | F12: 8 | G12: 4.5 | H12: 4.375 | I12: 4.25 | J12: 4.15 | K12: 4 | L12: 3.875
A13: I= 12 [A] | B13: 41 | C13: 12 | D13: 10 | E13: 8 | F13: 7 | G13: 4 | H13: 3.875 | I13: 3.75 | J13: 3.625 | K13: 3.5 | L13: 3.4
... A17: I= 16[A] | B17: 28 | C17: 7 | D17: 6.8 | E17: 6.3 | F17: 4.9 | G17: 2.75 | H17: 2.6 | I17: 2.55 | J17: 2.5 | K17: 2.45 | L17: 2.4

Sheet Vocv
A1: SOC | B1: Vocv (mV)
A2: 0 | B2: 2800
A3: 10 | B3: 3050
A4: 20 | B4: 3140
A5: 30 | B5: 3200
A6: 40 | B6: 3220
A7: 50 | B7: 3230
A8: 60 | B8: 3245
A9: 70 | B9: 3250
A10: 80 | B10: 3270
A11: 90 | B11: 3300
A12: 100 | B12: 3380

Sheet R2
B1: ="SOC = "&10*(COLUMN()-2)&" [%]" -> SOC = 0 [%] | C1: ="SOC = "&10*(COLUMN()-2)&" [%]" -> SOC = 10 [%] | D1: ="SOC = "&10*(COLUMN()-2)&" [%]" -> SOC = 20 [%] | E1: ="SOC = "&10*(COLUMN()-2)&" [%]" -> SOC = 30 [%] | F1: ="SOC = "&10*(COLUMN()-2)&" [%]" -> SOC = 40 [%] | G1: ="SOC = "&10*(COLUMN()-2)&" [%]" -> SOC = 50 [%] | H1: ="SOC = "&10*(COLUMN()-2)&" [%]" -> SOC = 60 [%] | I1: ="SOC = "&10*(COLUMN()-2)&" [%]" -> SOC = 70 [%] | ... L1: ="SOC = "&10*(COLUMN()-2)&" [%]" -> SOC = 100 [%]
A2: ="I= "&1*(row()-1)&" [A]" -> I= 1 [A] | B2: =0.85*150 -> 127.5 | C2: 120 | D2: 40 | E2: =D2+5 -> 45 | F2: =E2+3 -> 48 | G2: =F2-2 -> 46 | H2: =G2-5 -> 41 | I2: =H2-7 -> 34 | J2: =I2-3 -> 31 | K2: =J2+1 -> 32 | L2: =K2-2 -> 30
A3: ="I= "&1*(row()-1)&" [A]" -> I= 2 [A] | B3: 110 | C3: 105 | D3: 30 | E3: =D3+5 -> 35 | F3: =E3+3 -> 38 | G3: =F3-2 -> 36 | H3: =G3-5 -> 31 | I3: =H3-7 -> 24 | J3: =I3-3 -> 21 | K3: =J3+1 -> 22 | L3: =K3-2 -> 20
A4: ="I= "&1*(row()-1)&" [A]" -> I= 3 [A] | B4: 93 | C4: 85 | D4: 20 | E4: =D4+5 -> 25 | F4: =E4+3 -> 28 | G4: =F4-2 -> 26 | H4: =G4-5 -> 21 | I4: =H4-7 -> 14 | J4: =I4-1.5 -> 12.5 | K4: =J4+1.5 -> 14 | L4: =K4-2.5 -> 11.5
A5: ="I= "&1*(row()-1)&" [A]" -> I= 4 [A] | B5: 80 | C5: 72 | D5: 12 | E5: =D5+5 -> 17 | F5: =E5+3 -> 20 | G5: =F5-2 -> 18 | H5: =G5-5 -> 13 | I5: =H5-3 -> 10 | J5: =I5-2 -> 8 | K5: =J5+1.5 -> 9.5 | L5: =K5-2.5 -> 7
A6: ="I= "&1*(row()-1)&" [A]" -> I= 5 [A] | B6: 72 | C6: =B6*(C5/B5) -> 64.8 | D6: 8 | E6: =D6+5 -> 13 | F6: =E6+3 -> 16 | G6: =F6-2 -> 14 | H6: =G6-5 -> 9 | I6: =H6-3 -> 6 | J6: =I6-2 -> 4 | K6: =J6+1.5 -> 5.5 | L6: =K6-2.5 -> 3
A7: ="I= "&1*(row()-1)&" [A]" -> I= 6 [A] | B7: 65 | C7: =B7*(C6/B6) -> 58.5 | D7: 6 | E7: =D7+5 -> 11 | F7: =E7+3 -> 14 | G7: =F7-2 -> 12 | H7: =G7-5 -> 7 | I7: =H7-2 -> 5 | J7: =I7-1.5 -> 3.5 | K7: =J7+1.75 -> 5.25 | L7: =K7-2.5 -> 2.75
A8: ="I= "&1*(row()-1)&" [A]" -> I= 7 [A] | B8: 58 | C8: =B8*(C7/B7) -> 52.2 | D8: 5 | E8: =D8+5 -> 10 | F8: =E8+3 -> 13 | G8: =F8-2 -> 11 | H8: =G8-5 -> 6 | I8: =H8-2 -> 4 | J8: =I8-1.5 -> 2.5 | K8: =J8+1.75 -> 4.25 | L8: =K8-2 -> 2.25
A9: ="I= "&1*(row()-1)&" [A]" -> I= 8 [A] | B9: 51 | C9: =B9*(C8/B8) -> 45.9 | D9: 4 | E9: =D9+5 -> 9 | F9: =E9+3 -> 12 | G9: =F9-2 -> 10 | H9: =G9-5 -> 5 | I9: =H9-1.25 -> 3.75 | J9: =I9-1.5 -> 2.25 | K9: =J9+1.75 -> 4 | L9: =K9-1.75 -> 2.25
A10: ="I= "&1*(row()-1)&" [A]" -> I= 9 [A] | B10: 44 | C10: =B10*(C9/B9) -> 39.6 | D10: 4 | E10: =D10+5 -> 9 | F10: =E10+3 -> 12 | G10: =F10-2 -> 10 | H10: =G10-5 -> 5 | I10: =H10-2 -> 3 | J10: =I10-1.5 -> 1.5 | K10: =J10+1.75 -> 3.25 | L10: =K10-1.75 -> 1.5
A11: ="I= "&1*(row()-1)&" [A]" -> I= 10 [A] | B11: 40 | C11: =B11*(C10/B10) -> 36 | D11: 3.75 | E11: =D11+5 -> 8.75 | F11: =E11+3 -> 11.75 | G11: =F11-2 -> 9.75 | H11: =G11-5 -> 4.75 | I11: =H11-2 -> 2.75 | J11: =I11-1.5 -> 1.25 | K11: =J11+1.75 -> 3 | L11: =K11-1.75 -> 1.25
A12: ="I= "&1*(row()-1)&" [A]" -> I= 11 [A] | B12: 36 | C12: =B12*(C11/B11) -> 32.4 | D12: 3.5 | E12: =D12+5 -> 8.5 | F12: =E12+3 -> 11.5 | G12: =F12-2 -> 9.5 | H12: =G12-5 -> 4.5 | I12: =H12-2 -> 2.5 | J12: =I12-1 -> 1.5 | K12: =J12+1.8 -> 3.3 | L12: =K12-1.25 -> 2.05
A13: ="I= "&1*(row()-1)&" [A]" -> I= 12 [A] | B13: 33 | C13: =B13*(C12/B12) -> 29.7 | D13: 3.25 | E13: =D13+5 -> 8.25 | F13: =E13+3 -> 11.25 | G13: =F13-2 -> 9.25 | H13: =G13-5 -> 4.25 | I13: =H13-2 -> 2.25 | J13: =I13-1 -> 1.25 | K13: =J13+1.8 -> 3.05 | L13: =K13-1.25 -> 1.8
A14: ="I= "&1*(row()-1)&" [A]" -> I= 13 [A] | B14: 30 | C14: =B14*(C13/B13) -> 27 | D14: 3.125 | E14: =D14+5 -> 8.125 | F14: =E14+3 -> 11.125 | G14: =F14-2 -> 9.125 | H14: =G14-5 -> 4.125 | I14: =H14-2 -> 2.125 | J14: =I14-0.65 -> 1.475 | K14: =J14+1.8 -> 3.275 | L14: =K14-1.25 -> 2.025
A15: ="I= "&1*(row()-1)&" [A]" -> I= 14 [A] | B15: 28 | C15: =B15*(C14/B14) -> 25.2 | D15: 3 | E15: =D15+5 -> 8 | F15: =E15+3 -> 11 | G15: =F15-2 -> 9 | H15: =G15-5 -> 4 | I15: =H15-2 -> 2 | J15: =I15-0.65 -> 1.35 | K15: =J15+1.8 -> 3.15 | L15: =K15-1.25 -> 1.9
A16: ="I= "&1*(row()-1)&" [A]" -> I= 15 [A] | B16: 27 | C16: =B16*(C15/B15) -> 24.3 | D16: 3 | E16: =D16+5 -> 8 | F16: =E16+3 -> 11 | G16: =F16-2 -> 9 | H16: =G16-5 -> 4 | I16: =H16-2 -> 2 | J16: =I16-0.65 -> 1.35 | K16: =J16+1.8 -> 3.15 | L16: =K16-1.25 -> 1.9
A17: ="I= "&1*(row()-1)&" [A]" -> I= 16 [A] | B17: 25 | C17: =B17*(C16/B16) -> 22.5 | D17: 2.95 | E17: =D17+5 -> 7.95 | F17: =E17+3 -> 10.95 | G17: =F17-2 -> 8.95 | H17: =G17-5 -> 3.95 | I17: =H17-2 -> 1.95 | J17: =I17-0.65 -> 1.3 | K17: =J17+1.8 -> 3.1 | L17: =K17-1.25 -> 1.85

Sheet C2
B1: ="SOC = "&10*(COLUMN()-2)&" [%]" -> SOC = 0 [%] | C1: ="SOC = "&10*(COLUMN()-2)&" [%]" -> SOC = 10 [%] | D1: ="SOC = "&10*(COLUMN()-2)&" [%]" -> SOC = 20 [%] | E1: ="SOC = "&10*(COLUMN()-2)&" [%]" -> SOC = 30 [%] | F1: ="SOC = "&10*(COLUMN()-2)&" [%]" -> SOC = 40 [%] | G1: ="SOC = "&10*(COLUMN()-2)&" [%]" -> SOC = 50 [%] | H1: ="SOC = "&10*(COLUMN()-2)&" [%]" -> SOC = 60 [%] | I1: ="SOC = "&10*(COLUMN()-2)&" [%]" -> SOC = 70 [%] | ... L1: ="SOC = "&10*(COLUMN()-2)&" [%]" -> SOC = 100 [%]
A2: ="I= "&1*(row()-1)&" [A]" -> I= 1 [A] | B2: 45 | C2: 50 | D2: 58 | E2: 65 | F2: =E2+2 -> 67 | G2: =F2+2 -> 69 | H2: 73 | I2: 95 | J2: 125 | K2: 110 | L2: 120
A3: ="I= "&1*(row()-1)&" [A]" -> I= 2 [A] | B3: =0.52*100 -> 52 | C3: 52 | D3: 60 | E3: 70 | F3: =E3+2 -> 72 | G3: =F3+2 -> 74 | H3: 78 | I3: 105 | J3: 145 | K3: 125 | L3: 140
A4: ="I= "&1*(row()-1)&" [A]" -> I= 3 [A] | B4: 55 | C4: 56 | D4: =C4+10 -> 66 | E4: 75 | F4: 77 | G4: 79 | H4: 85 | I4: 110 | J4: 165 | K4: 135 | L4: 160
A5: ="I= "&1*(row()-1)&" [A]" -> I= 4 [A] | B5: 59 | C5: 61 | D5: =C5+10 -> 71 | E5: 90 | F5: 92 | G5: 93 | H5: 98 | I5: 125 | J5: 190 | K5: 150 | L5: 180
A6: ="I= "&1*(row()-1)&" [A]" -> I= 5 [A] | B6: 62 | C6: 65 | D6: =C6+10 -> 75 | E6: 99 | F6: 94 | G6: 95 | H6: 101 | I6: 135 | J6: 205 | K6: 165 | L6: 190
A7: ="I= "&1*(row()-1)&" [A]" -> I= 6 [A] | B7: 63 | C7: 69 | D7: =C7+10 -> 79 | E7: 109 | F7: 105 | G7: 106 | H7: 109 | I7: 170 | J7: 220 | K7: 180 | L7: 200
A8: ="I= "&1*(row()-1)&" [A]" -> I= 7 [A] | B8: 63.5 | C8: 70 | D8: =C8+10 -> 80 | E8: 120 | F8: 110 | G8: 109 | H8: 111 | I8: 190 | J8: 235 | K8: 190 | L8: 210
A9: ="I= "&1*(row()-1)&" [A]" -> I= 8 [A] | B9: 64 | C9: 70.5 | D9: =C9+10 -> 80.5 | E9: 122 | F9: 112 | G9: 111 | H9: 114 | I9: 210 | J9: 260 | K9: 200 | L9: 220
A10: ="I= "&1*(row()-1)&" [A]" -> I= 9 [A] | B10: 64.25 | C10: =B10+10 -> 74.25 | D10: =C10+10 -> 84.25 | E10: 124 | F10: 110 | G10: 111 | H10: 115 | I10: 230 | J10: 270 | K10: 205 | L10: 230
A11: ="I= "&1*(row()-1)&" [A]" -> I= 10 [A] | B11: 64.5 | C11: =B11+10 -> 74.5 | D11: =C11+10 -> 84.5 | E11: 126 | F11: 111 | G11: 112 | H11: 118 | I11: 250 | J11: 285 | K11: 210 | L11: 235
A12: ="I= "&1*(row()-1)&" [A]" -> I= 11 [A] | B12: 64.75 | C12: =B12+10 -> 74.75 | D12: =C12+10 -> 84.75 | E12: 127 | F12: 112 | G12: 113 | H12: 120 | I12: 280 | J12: 295 | K12: 212 | L12: 240
A13: ="I= "&1*(row()-1)&" [A]" -> I= 12 [A] | B13: 65 | C13: =B13+10 -> 75 | D13: =C13+10 -> 85 | E13: 128 | F13: 110 | G13: 107 | H13: 120 | I13: 300 | J13: 305 | K13: 210 | L13: 245
A14: ="I= "&1*(row()-1)&" [A]" -> I= 13 [A] | B14: 65.1 | C14: =B14+10 -> 75.1 | D14: =C14+10 -> 85.1 | E14: 127 | F14: 115 | G14: 112 | H14: 118 | I14: 310 | J14: 312 | K14: 215 | L14: 250
A15: ="I= "&1*(row()-1)&" [A]" -> I= 14 [A] | B15: 65.25 | C15: =B15+10 -> 75.25 | D15: =C15+10 -> 85.25 | E15: 125 | F15: 118 | G15: 116 | H15: 119 | I15: 318 | J15: 318 | K15: 220 | L15: 255
A16: ="I= "&1*(row()-1)&" [A]" -> I= 15 [A] | B16: 65.3 | C16: =B16+10 -> 75.3 | D16: =C16+10 -> 85.3 | E16: 124 | F16: 115 | G16: 115 | H16: 119 | I16: 320 | J16: 324 | K16: 225 | L16: 260
A17: ="I= "&1*(row()-1)&" [A]" -> I= 16 [A] | B17: 65.4 | C17: =B17+10 -> 75.4 | D17: =C17+10 -> 85.4 | E17: 125 | F17: 116 | G17: 114 | H17: 118 | I17: 325 | J17: 330 | K17: 230 | L17: 265

Sheet c2 - 1C2
A1: ='R2'!A1 | B1: ='R2'!B1 -> SOC = 0 [%] | C1: ='R2'!C1 -> SOC = 10 [%] | D1: ='R2'!D1 -> SOC = 20 [%] | E1: ='R2'!E1 -> SOC = 30 [%] | F1: ='R2'!F1 -> SOC = 40 [%] | G1: ='R2'!G1 -> SOC = 50 [%] | H1: ='R2'!H1 -> SOC = 60 [%] | ... L1: ='R2'!L1 -> SOC = 100 [%]
A2: ='R2'!A2 -> I= 1 [A] | B2: =1/('C2'!B2) -> 0.022222222 | C2: =1/('C2'!C2) -> 0.02 | D2: =1/('C2'!D2) -> 0.017241379 | E2: =1/('C2'!E2) -> 0.015384615 | F2: =1/('C2'!F2) -> 0.014925373 | G2: =1/('C2'!G2) -> 0.014492754 | H2: =1/('C2'!H2) -> 0.01369863 | I2: =1/('C2'!I2) -> 0.010526316 | ... L2: =1/('C2'!L2) -> 0.0083333333
A3: ='R2'!A3 -> I= 2 [A] | B3: =1/('C2'!B3) -> 0.019230769 | C3: =1/('C2'!C3) -> 0.019230769 | D3: =1/('C2'!D3) -> 0.016666667 | E3: =1/('C2'!E3) -> 0.014285714 | F3: =1/('C2'!F3) -> 0.013888889 | G3: =1/('C2'!G3) -> 0.013513514 | H3: =1/('C2'!H3) -> 0.012820513 | I3: =1/('C2'!I3) -> 0.0095238095 | ... L3: =1/('C2'!L3) -> 0.0071428571
A4: ='R2'!A4 -> I= 3 [A] | B4: =1/('C2'!B4) -> 0.018181818 | C4: =1/('C2'!C4) -> 0.017857143 | D4: =1/('C2'!D4) -> 0.015151515 | E4: =1/('C2'!E4) -> 0.013333333 | F4: =1/('C2'!F4) -> 0.012987013 | G4: =1/('C2'!G4) -> 0.012658228 | H4: =1/('C2'!H4) -> 0.011764706 | I4: =1/('C2'!I4) -> 0.0090909091 | ... L4: =1/('C2'!L4) -> 0.00625
A5: ='R2'!A5 -> I= 4 [A] | B5: =1/('C2'!B5) -> 0.016949153 | C5: =1/('C2'!C5) -> 0.016393443 | D5: =1/('C2'!D5) -> 0.014084507 | E5: =1/('C2'!E5) -> 0.011111111 | F5: =1/('C2'!F5) -> 0.010869565 | G5: =1/('C2'!G5) -> 0.010752688 | H5: =1/('C2'!H5) -> 0.010204082 | I5: =1/('C2'!I5) -> 0.008 | ... L5: =1/('C2'!L5) -> 0.0055555556
A6: ='R2'!A6 -> I= 5 [A] | B6: =1/('C2'!B6) -> 0.016129032 | C6: z | D6: =1/('C2'!D6) -> 0.013333333 | E6: =1/('C2'!E6) -> 0.01010101 | F6: =1/('C2'!F6) -> 0.010638298 | G6: =1/('C2'!G6) -> 0.010526316 | H6: =1/('C2'!H6) -> 0.0099009901 | I6: =1/('C2'!I6) -> 0.0074074074 | J6: =1/('C2'!J6) -> 0.0048780488 | K6: =1/('C2'!K6) -> 0.0060606061 | L6: =1/('C2'!L6) -> 0.0052631579
A7: ='R2'!A7 -> I= 6 [A] | B7: =1/('C2'!B7) -> 0.015873016 | C7: =1/('C2'!C7) -> 0.014492754 | D7: =1/('C2'!D7) -> 0.012658228 | E7: =1/('C2'!E7) -> 0.0091743119 | F7: =1/('C2'!F7) -> 0.0095238095 | G7: =1/('C2'!G7) -> 0.0094339623 | H7: =1/('C2'!H7) -> 0.0091743119 | I7: =1/('C2'!I7) -> 0.0058823529 | ... L7: =1/('C2'!L7) -> 0.005
A8: ='R2'!A8 -> I= 7 [A] | B8: =1/('C2'!B8) -> 0.015748031 | C8: =1/('C2'!C8) -> 0.014285714 | D8: =1/('C2'!D8) -> 0.0125 | E8: =1/('C2'!E8) -> 0.0083333333 | F8: =1/('C2'!F8) -> 0.0090909091 | G8: =1/('C2'!G8) -> 0.0091743119 | H8: =1/('C2'!H8) -> 0.009009009 | I8: =1/('C2'!I8) -> 0.0052631579 | ... L8: =1/('C2'!L8) -> 0.0047619048
A9: ='R2'!A9 -> I= 8 [A] | B9: =1/('C2'!B9) -> 0.015625 | C9: =1/('C2'!C9) -> 0.014184397 | D9: =1/('C2'!D9) -> 0.01242236 | E9: =1/('C2'!E9) -> 0.0081967213 | F9: =1/('C2'!F9) -> 0.0089285714 | G9: =1/('C2'!G9) -> 0.009009009 | H9: =1/('C2'!H9) -> 0.0087719298 | I9: =1/('C2'!I9) -> 0.0047619048 | ... L9: =1/('C2'!L9) -> 0.0045454545
A10: ='R2'!A10 -> I= 9 [A] | B10: =1/('C2'!B10) -> 0.015564202 | C10: =1/('C2'!C10) -> 0.013468013 | D10: =1/('C2'!D10) -> 0.011869436 | E10: =1/('C2'!E10) -> 0.0080645161 | F10: =1/('C2'!F10) -> 0.0090909091 | G10: =1/('C2'!G10) -> 0.009009009 | H10: =1/('C2'!H10) -> 0.0086956522 | I10: =1/('C2'!I10) -> 0.0043478261 | ... L10: =1/('C2'!L10) -> 0.0043478261
A11: ='R2'!A11 -> I= 10 [A] | B11: =1/('C2'!B11) -> 0.015503876 | C11: =1/('C2'!C11) -> 0.013422819 | D11: =1/('C2'!D11) -> 0.01183432 | E11: =1/('C2'!E11) -> 0.0079365079 | F11: =1/('C2'!F11) -> 0.009009009 | G11: =1/('C2'!G11) -> 0.0089285714 | H11: =1/('C2'!H11) -> 0.0084745763 | I11: =1/('C2'!I11) -> 0.004 | ... L11: =1/('C2'!L11) -> 0.0042553191
A12: ='R2'!A12 -> I= 11 [A] | B12: =1/('C2'!B12) -> 0.015444015 | C12: =1/('C2'!C12) -> 0.013377926 | D12: =1/('C2'!D12) -> 0.01179941 | E12: =1/('C2'!E12) -> 0.0078740157 | F12: =1/('C2'!F12) -> 0.0089285714 | G12: =1/('C2'!G12) -> 0.0088495575 | H12: =1/('C2'!H12) -> 0.0083333333 | I12: =1/('C2'!I12) -> 0.0035714286 | ... L12: =1/('C2'!L12) -> 0.0041666667
A13: ='R2'!A13 -> I= 12 [A] | B13: =1/('C2'!B13) -> 0.015384615 | C13: =1/('C2'!C13) -> 0.013333333 | D13: =1/('C2'!D13) -> 0.011764706 | E13: =1/('C2'!E13) -> 0.0078125 | F13: =1/('C2'!F13) -> 0.0090909091 | G13: =1/('C2'!G13) -> 0.0093457944 | H13: =1/('C2'!H13) -> 0.0083333333 | I13: =1/('C2'!I13) -> 0.0033333333 | ... L13: =1/('C2'!L13) -> 0.0040816327
A14: ='R2'!A14 -> I= 13 [A] | B14: =1/('C2'!B14) -> 0.015360983 | C14: =1/('C2'!C14) -> 0.013315579 | D14: =1/('C2'!D14) -> 0.011750881 | E14: =1/('C2'!E14) -> 0.0078740157 | F14: =1/('C2'!F14) -> 0.0086956522 | G14: =1/('C2'!G14) -> 0.0089285714 | H14: =1/('C2'!H14) -> 0.0084745763 | I14: =1/('C2'!I14) -> 0.0032258065 | ... L14: =1/('C2'!L14) -> 0.004
A15: ='R2'!A15 -> I= 14 [A] | B15: =1/('C2'!B15) -> 0.01532567 | C15: =1/('C2'!C15) -> 0.013289037 | D15: =1/('C2'!D15) -> 0.011730205 | E15: =1/('C2'!E15) -> 0.008 | F15: =1/('C2'!F15) -> 0.0084745763 | G15: =1/('C2'!G15) -> 0.0086206897 | H15: =1/('C2'!H15) -> 0.0084033613 | I15: =1/('C2'!I15) -> 0.0031446541 | ... L15: =1/('C2'!L15) -> 0.0039215686
A16: ='R2'!A16 -> I= 15 [A] | B16: =1/('C2'!B16) -> 0.015313936 | C16: =1/('C2'!C16) -> 0.013280212 | D16: =1/('C2'!D16) -> 0.011723329 | E16: =1/('C2'!E16) -> 0.0080645161 | F16: =1/('C2'!F16) -> 0.0086956522 | G16: =1/('C2'!G16) -> 0.0086956522 | H16: =1/('C2'!H16) -> 0.0084033613 | I16: =1/('C2'!I16) -> 0.003125 | ... L16: =1/('C2'!L16) -> 0.0038461538
A17: ='R2'!A17 -> I= 16 [A] | B17: =1/('C2'!B17) -> 0.01529052 | C17: =1/('C2'!C17) -> 0.013262599 | D17: =1/('C2'!D17) -> 0.011709602 | E17: =1/('C2'!E17) -> 0.008 | F17: =1/('C2'!F17) -> 0.0086206897 | G17: =1/('C2'!G17) -> 0.0087719298 | H17: =1/('C2'!H17) -> 0.0084745763 | I17: =1/('C2'!I17) -> 0.0030769231 | ... L17: =1/('C2'!L17) -> 0.0037735849

Sheet a2
A1: ='R2'!A1 | B1: ='R2'!B1 -> SOC = 0 [%] | C1: ='R2'!C1 -> SOC = 10 [%] | D1: ='R2'!D1 -> SOC = 20 [%] | E1: ='R2'!E1 -> SOC = 30 [%] | F1: ='R2'!F1 -> SOC = 40 [%] | G1: ='R2'!G1 -> SOC = 50 [%] | H1: ='R2'!H1 -> SOC = 60 [%] | ... L1: ='R2'!L1 -> SOC = 100 [%]
A2: ='R2'!A2 -> I= 1 [A] | B2: =1/('R2'!B2*'C2'!B2) -> 0.00017429194 | C2: =1/('R2'!C2*'C2'!C2) -> 0.00016666667 | D2: =1/('R2'!D2*'C2'!D2) -> 0.00043103448 | E2: =1/('R2'!E2*'C2'!E2) -> 0.00034188034 | F2: =1/('R2'!F2*'C2'!F2) -> 0.00031094527 | G2: =1/('R2'!G2*'C2'!G2) -> 0.00031505986 | H2: =1/('R2'!H2*'C2'!H2) -> 0.00033411293 | I2: =1/('R2'!I2*'C2'!I2) -> 0.00030959752 | ... L2: =1/('R2'!L2*'C2'!L2) -> 0.00027777778
A3: ='R2'!A3 -> I= 2 [A] | B3: =1/('R2'!B3*'C2'!B3) -> 0.00017482517 | C3: =1/('R2'!C3*'C2'!C3) -> 0.00018315018 | D3: =1/('R2'!D3*'C2'!D3) -> 0.00055555556 | E3: =1/('R2'!E3*'C2'!E3) -> 0.00040816327 | F3: =1/('R2'!F3*'C2'!F3) -> 0.00036549708 | G3: =1/('R2'!G3*'C2'!G3) -> 0.00037537538 | H3: =1/('R2'!H3*'C2'!H3) -> 0.00041356493 | I3: =1/('R2'!I3*'C2'!I3) -> 0.0003968254 | ... L3: =1/('R2'!L3*'C2'!L3) -> 0.00035714286
A4: ='R2'!A4 -> I= 3 [A] | B4: =1/('R2'!B4*'C2'!B4) -> 0.00019550342 | C4: =1/('R2'!C4*'C2'!C4) -> 0.00021008403 | D4: =1/('R2'!D4*'C2'!D4) -> 0.00075757576 | E4: =1/('R2'!E4*'C2'!E4) -> 0.00053333333 | F4: =1/('R2'!F4*'C2'!F4) -> 0.00046382189 | G4: =1/('R2'!G4*'C2'!G4) -> 0.00048685492 | H4: =1/('R2'!H4*'C2'!H4) -> 0.00056022409 | I4: =1/('R2'!I4*'C2'!I4) -> 0.00064935065 | ... L4: =1/('R2'!L4*'C2'!L4) -> 0.00054347826
A5: ='R2'!A5 -> I= 4 [A] | B5: =1/('R2'!B5*'C2'!B5) -> 0.00021186441 | C5: =1/('R2'!C5*'C2'!C5) -> 0.0002276867 | D5: =1/('R2'!D5*'C2'!D5) -> 0.0011737089 | E5: =1/('R2'!E5*'C2'!E5) -> 0.00065359477 | F5: =1/('R2'!F5*'C2'!F5) -> 0.00054347826 | G5: =1/('R2'!G5*'C2'!G5) -> 0.00059737157 | H5: =1/('R2'!H5*'C2'!H5) -> 0.00078492936 | I5: =1/('R2'!I5*'C2'!I5) -> 0.0008 | ... L5: =1/('R2'!L5*'C2'!L5) -> 0.00079365079
A6: ='R2'!A6 -> I= 5 [A] | B6: =1/('R2'!B6*'C2'!B6) -> 0.00022401434 | C6: =1/('R2'!C6*'C2'!C6) -> 0.0002374169 | D6: =1/('R2'!D6*'C2'!D6) -> 0.0016666667 | E6: =1/('R2'!E6*'C2'!E6) -> 0.00077700078 | F6: =1/('R2'!F6*'C2'!F6) -> 0.00066489362 | G6: =1/('R2'!G6*'C2'!G6) -> 0.0007518797 | H6: =1/('R2'!H6*'C2'!H6) -> 0.00110011 | I6: =1/('R2'!I6*'C2'!I6) -> 0.0012345679 | ... L6: =1/('R2'!L6*'C2'!L6) -> 0.001754386
A7: ='R2'!A7 -> I= 6 [A] | B7: =1/('R2'!B7*'C2'!B7) -> 0.00024420024 | C7: =1/('R2'!C7*'C2'!C7) -> 0.00024773938 | D7: =1/('R2'!D7*'C2'!D7) -> 0.0021097046 | E7: =1/('R2'!E7*'C2'!E7) -> 0.00083402836 | F7: =1/('R2'!F7*'C2'!F7) -> 0.00068027211 | G7: =1/('R2'!G7*'C2'!G7) -> 0.00078616352 | H7: =1/('R2'!H7*'C2'!H7) -> 0.001310616 | I7: =1/('R2'!I7*'C2'!I7) -> 0.0011764706 | ... L7: =1/('R2'!L7*'C2'!L7) -> 0.0018181818
A8: ='R2'!A8 -> I= 7 [A] | B8: =1/('R2'!B8*'C2'!B8) -> 0.00027151778 | C8: =1/('R2'!C8*'C2'!C8) -> 0.00027367269 | D8: =1/('R2'!D8*'C2'!D8) -> 0.0025 | E8: =1/('R2'!E8*'C2'!E8) -> 0.00083333333 | F8: =1/('R2'!F8*'C2'!F8) -> 0.0006993007 | G8: =1/('R2'!G8*'C2'!G8) -> 0.00083402836 | H8: =1/('R2'!H8*'C2'!H8) -> 0.0015015015 | I8: =1/('R2'!I8*'C2'!I8) -> 0.0013157895 | ... L8: =1/('R2'!L8*'C2'!L8) -> 0.0021164021
A9: ='R2'!A9 -> I= 8 [A] | B9: =1/('R2'!B9*'C2'!B9) -> 0.00030637255 | C9: =1/('R2'!C9*'C2'!C9) -> 0.00030902826 | D9: =1/('R2'!D9*'C2'!D9) -> 0.0031055901 | E9: =1/('R2'!E9*'C2'!E9) -> 0.00091074681 | F9: =1/('R2'!F9*'C2'!F9) -> 0.00074404762 | G9: =1/('R2'!G9*'C2'!G9) -> 0.0009009009 | H9: =1/('R2'!H9*'C2'!H9) -> 0.001754386 | I9: =1/('R2'!I9*'C2'!I9) -> 0.0012698413 | ... L9: =1/('R2'!L9*'C2'!L9) -> 0.002020202
A10: ='R2'!A10 -> I= 9 [A] | B10: =1/('R2'!B10*'C2'!B10) -> 0.00035373187 | C10: =1/('R2'!C10*'C2'!C10) -> 0.00034010135 | D10: =1/('R2'!D10*'C2'!D10) -> 0.002967359 | E10: =1/('R2'!E10*'C2'!E10) -> 0.00089605735 | F10: =1/('R2'!F10*'C2'!F10) -> 0.00075757576 | G10: =1/('R2'!G10*'C2'!G10) -> 0.0009009009 | H10: =1/('R2'!H10*'C2'!H10) -> 0.0017391304 | I10: =1/('R2'!I10*'C2'!I10) -> 0.0014492754 | ... L10: =1/('R2'!L10*'C2'!L10) -> 0.0028985507
A11: ='R2'!A11 -> I= 10 [A] | B11: =1/('R2'!B11*'C2'!B11) -> 0.0003875969 | C11: =1/('R2'!C11*'C2'!C11) -> 0.00037285608 | D11: =1/('R2'!D11*'C2'!D11) -> 0.0031558185 | E11: =1/('R2'!E11*'C2'!E11) -> 0.00090702948 | F11: =1/('R2'!F11*'C2'!F11) -> 0.00076672417 | G11: =1/('R2'!G11*'C2'!G11) -> 0.00091575092 | H11: =1/('R2'!H11*'C2'!H11) -> 0.0017841213 | I11: =1/('R2'!I11*'C2'!I11) -> 0.0014545455 | ... L11: =1/('R2'!L11*'C2'!L11) -> 0.0034042553
A12: ='R2'!A12 -> I= 11 [A] | B12: =1/('R2'!B12*'C2'!B12) -> 0.00042900043 | C12: =1/('R2'!C12*'C2'!C12) -> 0.00041289896 | D12: =1/('R2'!D12*'C2'!D12) -> 0.00337126 | E12: =1/('R2'!E12*'C2'!E12) -> 0.00092635479 | F12: =1/('R2'!F12*'C2'!F12) -> 0.00077639752 | G12: =1/('R2'!G12*'C2'!G12) -> 0.00093153237 | H12: =1/('R2'!H12*'C2'!H12) -> 0.0018518519 | I12: =1/('R2'!I12*'C2'!I12) -> 0.0014285714 | ... L12: =1/('R2'!L12*'C2'!L12) -> 0.0020325203
A13: ='R2'!A13 -> I= 12 [A] | B13: =1/('R2'!B13*'C2'!B13) -> 0.00046620047 | C13: =1/('R2'!C13*'C2'!C13) -> 0.00044893378 | D13: =1/('R2'!D13*'C2'!D13) -> 0.0036199095 | E13: =1/('R2'!E13*'C2'!E13) -> 0.0009469697 | F13: =1/('R2'!F13*'C2'!F13) -> 0.00080808081 | G13: =1/('R2'!G13*'C2'!G13) -> 0.0010103562 | H13: =1/('R2'!H13*'C2'!H13) -> 0.0019607843 | I13: =1/('R2'!I13*'C2'!I13) -> 0.0014814815 | ... L13: =1/('R2'!L13*'C2'!L13) -> 0.0022675737
... A17: ='R2'!A17 -> I= 16 [A] | B17: =1/('R2'!B17*'C2'!B17) -> 0.0006116208 | C17: =1/('R2'!C17*'C2'!C17) -> 0.00058944887 | D17: =1/('R2'!D17*'C2'!D17) -> 0.0039693566 | E17: =1/('R2'!E17*'C2'!E17) -> 0.0010062893 | F17: =1/('R2'!F17*'C2'!F17) -> 0.00078727759 | G17: =1/('R2'!G17*'C2'!G17) -> 0.00098010389 | H17: =1/('R2'!H17*'C2'!H17) -> 0.0021454623 | I17: =1/('R2'!I17*'C2'!I17) -> 0.0015779093 | ... L17: =1/('R2'!L17*'C2'!L17) -> 0.0020397756

Sheet C1
B1: ="SOC = "&10*(COLUMN()-2)&" [%]" -> SOC = 0 [%] | C1: ="SOC = "&10*(COLUMN()-2)&" [%]" -> SOC = 10 [%] | D1: ="SOC = "&10*(COLUMN()-2)&" [%]" -> SOC = 20 [%] | E1: ="SOC = "&10*(COLUMN()-2)&" [%]" -> SOC = 30 [%] | F1: ="SOC = "&10*(COLUMN()-2)&" [%]" -> SOC = 40 [%] | G1: ="SOC = "&10*(COLUMN()-2)&" [%]" -> SOC = 50 [%] | H1: ="SOC = "&10*(COLUMN()-2)&" [%]" -> SOC = 60 [%] | I1: ="SOC = "&10*(COLUMN()-2)&" [%]" -> SOC = 70 [%] | ... L1: ="SOC = "&10*(COLUMN()-2)&" [%]" -> SOC = 100 [%] | P1: kF
A2: ="I= "&1*(row()-1)&" [A]" -> I= 1 [A] | B2: 3.25 | C2: 4 | D2: 5 | E2: 6.75 | F2: 6.85 | G2: 7.75 | H2: 8 | I2: 9 | J2: 10 | K2: 11 | L2: 14
A3: ="I= "&1*(row()-1)&" [A]" -> I= 2 [A] | B3: 3.35 | C3: 5 | D3: 6.25 | E3: =D3+2 -> 8.25 | F3: 12.9 | G3: 13.9 | H3: 12.9 | I3: 12 | J3: 13.25 | K3: 18.25 | L3: 18.75
A4: ="I= "&1*(row()-1)&" [A]" -> I= 3 [A] | B4: 3.5 | C4: 6 | D4: 6.5 | E4: 8 | F4: 13.5 | G4: 15 | H4: 14.3 | I4: 12.3 | J4: 13.75 | K4: 18.5 | L4: 19.5
A5: ="I= "&1*(row()-1)&" [A]" -> I= 4 [A] | B5: 5 | C5: 5.5 | D5: 6 | E5: 10.5 | F5: 14 | G5: 15.5 | H5: 15.4 | I5: 12.5 | J5: 14 | K5: 18.75 | L5: 19.8
A6: ="I= "&1*(row()-1)&" [A]" -> I= 5 [A] | B6: 6 | C6: 5 | D6: 5.25 | E6: 12 | F6: 14.5 | G6: 16 | H6: 15.75 | I6: 12.8 | J6: 14.25 | K6: 19 | L6: 20
A7: ="I= "&1*(row()-1)&" [A]" -> I= 6 [A] | B7: 5 | C7: 4 | D7: 6 | E7: 12.75 | F7: 15 | G7: 16.25 | H7: 16 | I7: 13 | J7: 14.7 | K7: 19.3 | L7: 20.4
A8: ="I= "&1*(row()-1)&" [A]" -> I= 7 [A] | B8: 4.5 | C8: 4.35 | D8: 7 | E8: 13.25 | F8: 15.5 | G8: 16.4 | H8: 16.35 | I8: 13.25 | J8: 15 | K8: 19.6 | L8: 20.9
A9: ="I= "&1*(row()-1)&" [A]" -> I= 8 [A] | B9: 4.25 | C9: 4.5 | D9: 8 | E9: 13.75 | F9: 15.9 | G9: 16.7 | H9: 16.5 | I9: 13.5 | J9: 15.4 | K9: 20 | L9: 21.3
A10: ="I= "&1*(row()-1)&" [A]" -> I= 9 [A] | B10: 4 | C10: 5 | D10: 8.5 | E10: 14.25 | F10: 16.5 | G10: 17.2 | H10: 17 | I10: 14 | J10: 15.6 | K10: 19.7 | L10: 21
A11: ="I= "&1*(row()-1)&" [A]" -> I= 10 [A] | B11: 3.75 | C11: 6 | D11: 8.75 | E11: 14.85 | F11: 16.9 | G11: 17.5 | H11: 17.25 | I11: 13.75 | J11: 15.8 | K11: 19.6 | L11: 20
A12: ="I= "&1*(row()-1)&" [A]" -> I= 11 [A] | B12: 4 | C12: 7 | D12: 9 | E12: 14.25 | F12: 16.4 | G12: 17.3 | H12: 16.9 | I12: 14 | J12: 16 | K12: 18 | L12: 19.5
A13: ="I= "&1*(row()-1)&" [A]" -> I= 12 [A] | B13: 3.85 | C13: 5.6 | D13: 8.5 | E13: 13 | F13: 15.6 | G13: 16 | H13: 15.5 | I13: 13.5 | J13: 15.7 | K13: 16 | L13: 17
A14: ="I= "&1*(row()-1)&" [A]" -> I= 13 [A] | B14: 3.6 | C14: 5 | D14: 7.5 | E14: 11.75 | F14: 14.5 | G14: 15 | H14: 14.95 | I14: 13 | J14: 15 | K14: 15 | L14: 15.5
A15: ="I= "&1*(row()-1)&" [A]" -> I= 14 [A] | B15: 3.65 | C15: 4.95 | D15: 6.5 | E15: 10.25 | F15: 13.25 | G15: 14 | H15: 14.1 | I15: 12.6 | J15: 14 | K15: 14 | L15: 14.7
... A17: ="I= "&1*(row()-1)&" [A]" -> I= 16 [A] | B17: 4.25 | C17: 4.5 | D17: 5 | E17: 8 | F17: 10.5 | G17: 11.5 | H17: 11 | I17: 12 | J17: 12.4 | K17: 13 | L17: 13.5

Sheet c1 1C1
A1: ='C1'!A1 | B1: ='C1'!B1 -> SOC = 0 [%] | C1: ='C1'!C1 -> SOC = 10 [%] | D1: ='C1'!D1 -> SOC = 20 [%] | E1: ='C1'!E1 -> SOC = 30 [%] | F1: ='C1'!F1 -> SOC = 40 [%] | G1: ='C1'!G1 -> SOC = 50 [%] | H1: ='C1'!H1 -> SOC = 60 [%] | ... L1: ='C1'!L1 -> SOC = 100 [%]
A2: ='C1'!A2 -> I= 1 [A] | B2: =1/'C1'!B2 -> 0.30769231 | C2: =1/'C1'!C2 -> 0.25 | D2: =1/'C1'!D2 -> 0.2 | E2: =1/'C1'!E2 -> 0.14814815 | F2: =1/'C1'!F2 -> 0.1459854 | G2: =1/'C1'!G2 -> 0.12903226 | H2: =1/'C1'!H2 -> 0.125 | I2: =1/'C1'!I2 -> 0.11111111 | ... L2: =1/'C1'!L2 -> 0.071428571
A3: ='C1'!A3 -> I= 2 [A] | B3: =1/'C1'!B3 -> 0.29850746 | C3: =1/'C1'!C3 -> 0.2 | D3: =1/'C1'!D3 -> 0.16 | E3: =1/'C1'!E3 -> 0.12121212 | F3: =1/'C1'!F3 -> 0.07751938 | G3: =1/'C1'!G3 -> 0.071942446 | H3: =1/'C1'!H3 -> 0.07751938 | I3: =1/'C1'!I3 -> 0.083333333 | ... L3: =1/'C1'!L3 -> 0.053333333
A4: ='C1'!A4 -> I= 3 [A] | B4: =1/'C1'!B4 -> 0.28571429 | C4: =1/'C1'!C4 -> 0.16666667 | D4: =1/'C1'!D4 -> 0.15384615 | E4: =1/'C1'!E4 -> 0.125 | F4: =1/'C1'!F4 -> 0.074074074 | G4: =1/'C1'!G4 -> 0.066666667 | H4: =1/'C1'!H4 -> 0.06993007 | I4: =1/'C1'!I4 -> 0.081300813 | ... L4: =1/'C1'!L4 -> 0.051282051
A5: ='C1'!A5 -> I= 4 [A] | B5: =1/'C1'!B5 -> 0.2 | C5: =1/'C1'!C5 -> 0.18181818 | D5: =1/'C1'!D5 -> 0.16666667 | E5: =1/'C1'!E5 -> 0.095238095 | F5: =1/'C1'!F5 -> 0.071428571 | G5: =1/'C1'!G5 -> 0.064516129 | H5: =1/'C1'!H5 -> 0.064935065 | I5: =1/'C1'!I5 -> 0.08 | ... L5: =1/'C1'!L5 -> 0.050505051
A6: ='C1'!A6 -> I= 5 [A] | B6: =1/'C1'!B6 -> 0.16666667 | C6: =1/'C1'!C6 -> 0.2 | D6: =1/'C1'!D6 -> 0.19047619 | E6: =1/'C1'!E6 -> 0.083333333 | F6: =1/'C1'!F6 -> 0.068965517 | G6: =1/'C1'!G6 -> 0.0625 | H6: =1/'C1'!H6 -> 0.063492063 | I6: =1/'C1'!I6 -> 0.078125 | ... L6: =1/'C1'!L6 -> 0.05
A7: ='C1'!A7 -> I= 6 [A] | B7: =1/'C1'!B7 -> 0.2 | C7: =1/'C1'!C7 -> 0.25 | D7: =1/'C1'!D7 -> 0.16666667 | E7: =1/'C1'!E7 -> 0.078431373 | F7: =1/'C1'!F7 -> 0.066666667 | G7: =1/'C1'!G7 -> 0.061538462 | H7: =1/'C1'!H7 -> 0.0625 | I7: =1/'C1'!I7 -> 0.076923077 | ... L7: =1/'C1'!L7 -> 0.049019608
A8: ='C1'!A8 -> I= 7 [A] | B8: =1/'C1'!B8 -> 0.22222222 | C8: =1/'C1'!C8 -> 0.22988506 | D8: =1/'C1'!D8 -> 0.14285714 | E8: =1/'C1'!E8 -> 0.075471698 | F8: =1/'C1'!F8 -> 0.064516129 | G8: =1/'C1'!G8 -> 0.06097561 | H8: =1/'C1'!H8 -> 0.06116208 | I8: =1/'C1'!I8 -> 0.075471698 | ... L8: =1/'C1'!L8 -> 0.04784689
A9: ='C1'!A9 -> I= 8 [A] | B9: =1/'C1'!B9 -> 0.23529412 | C9: =1/'C1'!C9 -> 0.22222222 | D9: =1/'C1'!D9 -> 0.125 | E9: =1/'C1'!E9 -> 0.072727273 | F9: =1/'C1'!F9 -> 0.062893082 | G9: =1/'C1'!G9 -> 0.05988024 | H9: =1/'C1'!H9 -> 0.060606061 | I9: =1/'C1'!I9 -> 0.074074074 | ... L9: =1/'C1'!L9 -> 0.046948357
A10: ='C1'!A10 -> I= 9 [A] | B10: =1/'C1'!B10 -> 0.25 | C10: =1/'C1'!C10 -> 0.2 | D10: =1/'C1'!D10 -> 0.11764706 | E10: =1/'C1'!E10 -> 0.070175439 | F10: =1/'C1'!F10 -> 0.060606061 | G10: =1/'C1'!G10 -> 0.058139535 | H10: =1/'C1'!H10 -> 0.058823529 | I10: =1/'C1'!I10 -> 0.071428571 | ... L10: =1/'C1'!L10 -> 0.047619048
A11: ='C1'!A11 -> I= 10 [A] | B11: =1/'C1'!B11 -> 0.26666667 | C11: =1/'C1'!C11 -> 0.16666667 | D11: =1/'C1'!D11 -> 0.11428571 | E11: =1/'C1'!E11 -> 0.067340067 | F11: =1/'C1'!F11 -> 0.059171598 | G11: =1/'C1'!G11 -> 0.057142857 | H11: =1/'C1'!H11 -> 0.057971014 | I11: =1/'C1'!I11 -> 0.072727273 | ... L11: =1/'C1'!L11 -> 0.05
A12: ='C1'!A12 -> I= 11 [A] | B12: =1/'C1'!B12 -> 0.25 | C12: =1/'C1'!C12 -> 0.14285714 | D12: =1/'C1'!D12 -> 0.11111111 | E12: =1/'C1'!E12 -> 0.070175439 | F12: =1/'C1'!F12 -> 0.06097561 | G12: =1/'C1'!G12 -> 0.057803468 | H12: =1/'C1'!H12 -> 0.059171598 | I12: =1/'C1'!I12 -> 0.071428571 | ... L12: =1/'C1'!L12 -> 0.051282051
A13: ='C1'!A13 -> I= 12 [A] | B13: =1/'C1'!B13 -> 0.25974026 | C13: =1/'C1'!C13 -> 0.17857143 | D13: =1/'C1'!D13 -> 0.11764706 | E13: =1/'C1'!E13 -> 0.076923077 | F13: =1/'C1'!F13 -> 0.064102564 | G13: =1/'C1'!G13 -> 0.0625 | H13: =1/'C1'!H13 -> 0.064516129 | I13: =1/'C1'!I13 -> 0.074074074 | ... L13: =1/'C1'!L13 -> 0.058823529
... A17: ='C1'!A17 -> I= 16 [A] | B17: =1/'C1'!B17 -> 0.23529412 | C17: =1/'C1'!C17 -> 0.22222222 | D17: =1/'C1'!D17 -> 0.2 | E17: =1/'C1'!E17 -> 0.125 | F17: =1/'C1'!F17 -> 0.095238095 | G17: =1/'C1'!G17 -> 0.086956522 | H17: =1/'C1'!H17 -> 0.090909091 | I17: =1/'C1'!I17 -> 0.083333333 | ... L17: =1/'C1'!L17 -> 0.074074074

Sheet a1 (1(R1C1))
B1: SOC = 0 [%] | C1: SOC = 10 [%] | D1: SOC = 20 [%] | E1: SOC = 30 [%] | F1: SOC = 40 [%] | G1: SOC = 50 [%] | H1: SOC = 60 [%] | I1: SOC = 70 [%] | J1: SOC = 80 [%] | K1: SOC = 90 [%] | L1: SOC = 100 [%] | M1: =A1 | N1: =B1 -> SOC = 0 [%] | O1: =C1 -> SOC = 10 [%] | P1: =D1 -> SOC = 20 [%] | Q1: =E1 -> SOC = 30 [%] | R1: =F1 -> SOC = 40 [%] | S1: =G1 -> SOC = 50 [%] | T1: =H1 -> SOC = 60 [%] | ... X1: =L1 -> SOC = 100 [%]
A2: I= 1 [A] | B2: 0.0031558185 | C2: 0.005 | D2: 0.01 | E2: 0.0098765432 | F2: 0.01216545 | G2: 0.012903226 | H2: 0.013888889 | I2: 0.013071895 | J2: 0.012121212 | K2: 0.011363636 | L2: 0.0090702948 | M2: =A2 -> I= 1 [A] | N2: =(2^5)*B2 -> 0.10098619 | O2: =(2^5)*C2 -> 0.16 | P2: =(2^5)*D2 -> 0.32 | Q2: =(2^5)*E2 -> 0.31604938 | R2: =(2^5)*F2 -> 0.3892944 | S2: =(2^5)*G2 -> 0.41290323 | T2: =(2^5)*H2 -> 0.44444444 | U2: =(2^5)*I2 -> 0.41830065 | ... X2: =(2^5)*L2 -> 0.29024943
A3: I= 2 [A] | B3: 0.0035964755 | C3: 0.0046987952 | D3: 0.0093975904 | E3: 0.0094925155 | F3: 0.0075884935 | G3: 0.0073787124 | H3: 0.0088341174 | I3: 0.010055304 | J3: 0.0093826509 | K3: 0.0070249385 | L3: 0.0069461403 | M3: =A3 -> I= 2 [A] | N3: =(2^5)*B3 -> 0.11508721 | O3: =(2^5)*C3 -> 0.15036145 | P3: =(2^5)*D3 -> 0.30072289 | Q3: =(2^5)*E3 -> 0.3037605 | R3: =(2^5)*F3 -> 0.24283179 | S3: =(2^5)*G3 -> 0.2361188 | T3: =(2^5)*H3 -> 0.28269176 | U3: =(2^5)*I3 -> 0.32176973 | ... X3: =(2^5)*L3 -> 0.22227649
A4: I= 3 [A] | B4: 0.0037593985 | C4: 0.0042763158 | D4: 0.0098684211 | E4: 0.010690789 | F4: 0.0044376173 | G4: 0.0070175439 | H4: 0.0081789555 | I4: 0.010068212 | J4: 0.0092793968 | K4: 0.0071123755 | L4: 0.0068547437 | M4: =A4 -> I= 3 [A] | N4: =(2^5)*B4 -> 0.12030075 | O4: =(2^5)*C4 -> 0.13684211 | P4: =(2^5)*D4 -> 0.31578947 | Q4: =(2^5)*E4 -> 0.34210526 | R4: =(2^5)*F4 -> 0.14200375 | S4: =(2^5)*G4 -> 0.2245614 | T4: =(2^5)*H4 -> 0.26172658 | U4: =(2^5)*I4 -> 0.32218279 | ... X4: =(2^5)*L4 -> 0.2193518
A5: I= 4 [A] | B5: 0.0028985507 | C5: 0.0051383399 | D5: 0.011775362 | E5: 0.0089717046 | F5: 0.0045742435 | G5: 0.006863418 | H5: 0.0076755396 | I5: 0.010012516 | J5: 0.0092106475 | K5: 0.0070921986 | L5: 0.0068227019 | M5: =A5 -> I= 4 [A] | N5: =(2^5)*B5 -> 0.092753623 | O5: =(2^5)*C5 -> 0.16442688 | P5: =(2^5)*D5 -> 0.37681159 | Q5: =(2^5)*E5 -> 0.28709455 | R5: =(2^5)*F5 -> 0.14637579 | S5: =(2^5)*G5 -> 0.21962938 | T5: =(2^5)*H5 -> 0.24561727 | U5: =(2^5)*I5 -> 0.3204005 | ... X5: =(2^5)*L5 -> 0.21832646
A6: I= 5 [A] | B6: 0.0026455026 | C6: 0.0061904762 | D6: 0.014739229 | E6: 0.0085978836 | F6: 0.0046939881 | G6: 0.0067567568 | H6: 0.0076266743 | I6: 0.009936407 | J6: 0.0091957987 | K6: 0.0071123755 | L6: 0.0068640069 | M6: =A6 -> I= 5 [A] | N6: =(2^5)*B6 -> 0.084656085 | O6: =(2^5)*C6 -> 0.19809524 | P6: =(2^5)*D6 -> 0.47165533 | Q6: =(2^5)*E6 -> 0.27513228 | R6: =(2^5)*F6 -> 0.15020762 | S6: =(2^5)*G6 -> 0.21621622 | T6: =(2^5)*H6 -> 0.24405358 | U6: =(2^5)*I6 -> 0.31796502 | ... X6: =(2^5)*L6 -> 0.21964822
A7: I= 6 [A] | B7: 0.0034482759 | C7: 0.0084051724 | D7: 0.014008621 | E7: 0.0087897228 | F7: 0.0047882136 | G7: 0.006743941 | H7: 0.0076103501 | I7: 0.0099175603 | J7: 0.0090364083 | K7: 0.0070977358 | L7: 0.0068216023 | M7: =A7 -> I= 6 [A] | N7: =(2^5)*B7 -> 0.11034483 | O7: =(2^5)*C7 -> 0.26896552 | P7: =(2^5)*D7 -> 0.44827586 | Q7: =(2^5)*E7 -> 0.28127113 | R7: =(2^5)*F7 -> 0.15322284 | S7: =(2^5)*G7 -> 0.21580611 | T7: =(2^5)*H7 -> 0.2435312 | U7: =(2^5)*I7 -> 0.31736193 | ... X7: =(2^5)*L7 -> 0.21829127
A8: I= 7 [A] | B8: 0.0041928721 | C8: 0.0084580351 | D8: 0.013140162 | E8: 0.009255963 | F8: 0.004904735 | G8: 0.0067750678 | H8: 0.007550874 | I8: 0.0098655815 | J8: 0.0089786756 | K8: 0.0070861678 | L8: 0.0067508839 | M8: =A8 -> I= 7 [A] | N8: =(2^5)*B8 -> 0.13417191 | O8: =(2^5)*C8 -> 0.27065712 | P8: =(2^5)*D8 -> 0.42048518 | Q8: =(2^5)*E8 -> 0.29619082 | R8: =(2^5)*F8 -> 0.15695152 | S8: =(2^5)*G8 -> 0.21680217 | T8: =(2^5)*H8 -> 0.24162797 | U8: =(2^5)*I8 -> 0.31569861 | ... X8: =(2^5)*L8 -> 0.21602829
A9: I= 8 [A] | B9: 0.0049019608 | C9: 0.0090277778 | D9: 0.012695312 | E9: 0.0098484848 | F9: 0.0050783234 | G9: 0.0067092705 | H9: 0.0075451056 | I9: 0.0097642543 | J9: 0.0088189546 | K9: 0.0070028011 | L9: 0.0066797715 | M9: =A9 -> I= 8 [A] | N9: =(2^5)*B9 -> 0.15686275 | O9: =(2^5)*C9 -> 0.28888889 | P9: =(2^5)*D9 -> 0.40625 | Q9: =(2^5)*E9 -> 0.31515152 | R9: =(2^5)*F9 -> 0.16250635 | S9: =(2^5)*G9 -> 0.21469666 | T9: =(2^5)*H9 -> 0.24144338 | U9: =(2^5)*I9 -> 0.31245614 | ... X9: =(2^5)*L9 -> 0.21375269
A10: I= 9 [A] | B10: 0.0056818182 | C10: 0.0088636364 | D10: 0.013034759 | E10: 0.010366826 | F10: 0.0051495346 | G10: 0.0065509335 | H10: 0.0073644481 | I10: 0.0094685762 | J10: 0.0087549383 | K10: 0.007149496 | L10: 0.006813367 | M10: =A10 -> I= 9 [A] | N10: =(2^5)*B10 -> 0.18181818 | O10: =(2^5)*C10 -> 0.28363636 | P10: =(2^5)*D10 -> 0.4171123 | Q10: =(2^5)*E10 -> 0.33173844 | R10: =(2^5)*F10 -> 0.16478511 | S10: =(2^5)*G10 -> 0.20962987 | T10: =(2^5)*H10 -> 0.23566234 | U10: =(2^5)*I10 -> 0.30299444 | ... X10: =(2^5)*L10 -> 0.21802774
A11: I= 10 [A] | B11: 0.0066666667 | C11: 0.008125 | D11: 0.012355212 | E11: 0.0092882852 | F11: 0.0048303345 | G11: 0.0067226891 | H11: 0.0075779104 | I11: 0.010066059 | J11: 0.0090254744 | K11: 0.0075030012 | L11: 0.0074696545 | M11: =A11 -> I= 10 [A] | N11: =(2^5)*B11 -> 0.21333333 | O11: =(2^5)*C11 -> 0.26 | P11: =(2^5)*D11 -> 0.3953668 | Q11: =(2^5)*E11 -> 0.29722512 | R11: =(2^5)*F11 -> 0.1545707 | S11: =(2^5)*G11 -> 0.21512605 | T11: =(2^5)*H11 -> 0.24249313 | U11: =(2^5)*I11 -> 0.32211387 | ... X11: =(2^5)*L11 -> 0.23902894
A12: I= 11 [A] | B12: 0.0069444444 | C12: 0.0077380952 | D12: 0.011396011 | E12: 0.0091829928 | F12: 0.0048232978 | G12: 0.007006481 | H12: 0.0079692387 | I12: 0.010185893 | J12: 0.0091827365 | K12: 0.0084175084 | L12: 0.0078933412 | M12: =A12 -> I= 11 [A] | N12: =(2^5)*B12 -> 0.22222222 | O12: =(2^5)*C12 -> 0.24761905 | P12: =(2^5)*D12 -> 0.36467236 | Q12: =(2^5)*E12 -> 0.29385577 | R12: =(2^5)*F12 -> 0.15434553 | S12: =(2^5)*G12 -> 0.22420739 | T12: =(2^5)*H12 -> 0.25501564 | U12: =(2^5)*I12 -> 0.32594856 | ... X12: =(2^5)*L12 -> 0.25258692
A13: I= 12 [A] | B13: 0.007870917 | C13: 0.010551948 | D13: 0.011204482 | E13: 0.0093469749 | F13: 0.0048453419 | G13: 0.0078125 | H13: 0.0089605735 | I13: 0.010893246 | J13: 0.0096506466 | K13: 0.009765625 | L13: 0.0093370682 | M13: =A13 -> I= 12 [A] | N13: =(2^5)*B13 -> 0.25186934 | O13: =(2^5)*C13 -> 0.33766234 | P13: =(2^5)*D13 -> 0.35854342 | Q13: =(2^5)*E13 -> 0.2991032 | R13: =(2^5)*F13 -> 0.15505094 | S13: =(2^5)*G13 -> 0.25 | T13: =(2^5)*H13 -> 0.28673835 | U13: =(2^5)*I13 -> 0.34858388 | ... X13: =(2^5)*L13 -> 0.29878618
... A17: I= 16 [A] | B17: 0.0094117647 | C17: 0.017333333 | D17: 0.013333333 | E17: 0.0069444444 | F17: 0.0063492063 | G17: 0.0086956522 | H17: 0.01010101 | I17: 0.0098039216 | J17: 0.0097751711 | K17: 0.011362345 | L17: 0.011287478 | M17: =A17 -> I= 16 [A] | N17: =(2^5)*B17 -> 0.30117647 | O17: =(2^5)*C17 -> 0.55466667 | P17: =(2^5)*D17 -> 0.42666667 | Q17: =(2^5)*E17 -> 0.22222222 | R17: =(2^5)*F17 -> 0.2031746 | S17: =(2^5)*G17 -> 0.27826087 | T17: =(2^5)*H17 -> 0.32323232 | U17: =(2^5)*I17 -> 0.31372549 | ... X17: =(2^5)*L17 -> 0.36119929
B24: ="SOC = "&10*(COLUMN()-2)&" [%]" -> SOC = 0 [%] | C24: ="SOC = "&10*(COLUMN()-2)&" [%]" -> SOC = 10 [%] | D24: ="SOC = "&10*(COLUMN()-2)&" [%]" -> SOC = 20 [%] | E24: ="SOC = "&10*(COLUMN()-2)&" [%]" -> SOC = 30 [%] | F24: ="SOC = "&10*(COLUMN()-2)&" [%]" -> SOC = 40 [%] | G24: ="SOC = "&10*(COLUMN()-2)&" [%]" -> SOC = 50 [%] | H24: ="SOC = "&10*(COLUMN()-2)&" [%]" -> SOC = 60 [%] | I24: ="SOC = "&10*(COLUMN()-2)&" [%]" -> SOC = 70 [%] | ... L24: ="SOC = "&10*(COLUMN()-2)&" [%]" -> SOC = 100 [%] | N24: ="SOC = "&10*(COLUMN()-14)&" [%]" -> SOC = 0 [%] | O24: ="SOC = "&10*(COLUMN()-14)&" [%]" -> SOC = 10 [%] | P24: ="SOC = "&10*(COLUMN()-14)&" [%]" -> SOC = 20 [%] | Q24: ="SOC = "&10*(COLUMN()-14)&" [%]" -> SOC = 30 [%] | R24: ="SOC = "&10*(COLUMN()-14)&" [%]" -> SOC = 40 [%] | S24: ="SOC = "&10*(COLUMN()-14)&" [%]" -> SOC = 50 [%] | T24: ="SOC = "&10*(COLUMN()-14)&" [%]" -> SOC = 60 [%] | U24: ="SOC = "&10*(COLUMN()-14)&" [%]" -> SOC = 70 [%] | ... X24: ="SOC = "&10*(COLUMN()-14)&" [%]" -> SOC = 100 [%]
